<?xml version="1.0" encoding="utf-8"?>
<robot
  name="oberon7">
    <link name="base">
        <inertial>
          <origin rpy="0 0 0" xyz="-0.101581 -0.001371 -0.009781"/>
          <mass value="9.67467717018"/>
          <inertia ixx="0.0511731678147" ixy="0.0" ixz="0.0" iyy="0.0836771724144" iyz="0.0" izz="0.0958032978152"/>
        </inertial>

        <visual>
            <origin xyz="0 0 0" rpy="0 0 0"/>
            <geometry>
                <mesh filename="package://rexrov_dual_oberon_description/meshes/Base.stl"/>
            </geometry>
        </visual>

        <collision>
            <origin xyz="0 0 0" rpy="0 0 0"/>
            <geometry>
                <mesh filename="package://rexrov_dual_oberon_description/meshes/Base.stl"/>
            </geometry>
        </collision>
    </link>

    <link name="shoulder_link">
        <inertial>
          <origin rpy="0 0 0" xyz="0.039670 0.005441 0.017383"/>
          <mass value="6.72225246901"/>
          <inertia ixx="0.0425839738294" ixy="0.0" ixz="0.0" iyy="0.0513257548564" iyz="0.0" izz="0.0295765413777"/>
        </inertial>

        <visual>
            <origin xyz="0 0 0" rpy="0 0 0"/>
            <geometry>
                <mesh filename="package://rexrov_dual_oberon_description/meshes/ShoulderLink.stl"/>
            </geometry>
        </visual>

        <collision>
          <origin rpy="0 0 0" xyz="0.039670 0.005441 0.017383"/>
          <geometry>
            <cylinder length="0.239627" radius="0.068184"/>
          </geometry>
        </collision>
    </link>

    <joint name="azimuth" type="revolute">
        <parent link="base"/>
        <child link="shoulder_link"/>
        <axis xyz="0 0 1"/>
        <limit effort="200" lower="-1.04719758" upper="1.04719758" velocity="0.17"/>
    </joint>


    <link name="upper_arm">
        <inertial>
          <origin rpy="0 0 0" xyz="0.312501 0.017478 -0.000002"/>
          <mass value="12.4443999072"/>
          <inertia ixx="0.0378234483246" ixy="0.0" ixz="0.0" iyy="0.411488180504" iyz="0.0" izz="0.415420854645"/>
        </inertial>

        <visual>
            <origin xyz="0 0 0" rpy="0 0 0"/>
            <geometry>
                <mesh filename="package://rexrov_dual_oberon_description/meshes/UpperArm.stl"/>
            </geometry>
        </visual>

        <collision>
          <origin rpy="0 1.57079632679 0" xyz="0.312501 0.017478 -0.000002"/>
          <geometry>
            <cylinder length="0.616809" radius="0.0709445"/>
          </geometry>
        </collision>
    </link>

    <joint name="shoulder" type="revolute">
        <parent link="shoulder_link"/>
        <child link="upper_arm"/>
        <origin rpy="1.57079632679 0 0" xyz="0.06955 0.00015 0.01536"/>
        <axis xyz="0 0 1"/>
        <limit effort="5000" lower="-1.57079637" upper="1.57079637" velocity=".17"/>
    </joint>

    <link name="elbow_link">
        <inertial>
          <origin rpy="0 0 0" xyz="0.125269 -0.074675 0.0"/>
          <mass value="10.3145088675"/>
          <inertia ixx="0.0717197873733" ixy="0.0" ixz="0.0" iyy="0.0724090834438" iyz="0.0" izz="0.10276175034"/>
        </inertial>

        <visual>
            <origin xyz="0 0 0" rpy="0 0 0"/>
            <geometry>
                <mesh filename="package://rexrov_dual_oberon_description/meshes/ElbowLink.stl"/>
            </geometry>
        </visual>

        <collision>
          <origin rpy="0 1.57079632679 1.57079632679" xyz="0.125269 -0.074675 0.0"/>
          <geometry>
            <cylinder length="0.245312" radius="0.077562"/>
          </geometry>
        </collision>
    </link>

    <joint name="elbow" type="revolute">
        <parent link="upper_arm"/>
        <child link="elbow_link"/>
        <origin xyz="0.55616 -0.01229 0" rpy="0 0 0"/>
        <axis xyz="0 0 1"/>
        <limit effort="300" lower="-1.57079637" upper="1.04719758" velocity=".13"/>
    </joint>

    <link name="forearm">
        <inertial>
          <origin rpy="0 0 0" xyz="0 0 0.157978803149"/>
          <mass value="8.54626175585"/>
          <inertia ixx="0.0961794420773" ixy="0.0" ixz="0.0" iyy="0.0961902303084" iyz="0.0" izz="0.0326840256692"/>
        </inertial>

        <visual>
            <origin xyz="0 0 0" rpy="0 0 0"/>
            <geometry>
                <mesh filename="package://rexrov_dual_oberon_description/meshes/Forearm.stl"/>
            </geometry>
        </visual>

        <collision>
          <origin rpy="0 0 0" xyz="0 0 0.157978803149"/>
          <geometry>
            <cylinder length="0.334827" radius="0.0757275"/>
          </geometry>
        </collision>
    </link>

    <joint name="roll" type="revolute">
        <parent link="elbow_link"/>
        <child link="forearm"/>
        <origin rpy="1.57079632679 0 0" xyz="0.1349014 -0.1936267 0"/>
        <axis xyz="0 0 1"/>
        <limit effort="200" lower="-2.356194555" upper="2.356194555" velocity=".085"/>
    </joint>

    <link name="wrist_link">
        <inertial>
          <origin rpy="0 0 0" xyz="0.104016 0.003308 -0.000027"/>
          <mass value="3.9024235777"/>
          <inertia ixx="0.0104282209379" ixy="0.0" ixz="0.0" iyy="0.0211536636614" iyz="0.0" izz="0.020526721979"/>
        </inertial>

        <visual>
            <origin xyz="0 0 0" rpy="0 0 0"/>
            <geometry>
                <mesh filename="package://rexrov_dual_oberon_description/meshes/Wrist.stl"/>
            </geometry>
        </visual>

        <collision>
          <origin rpy="0 1.57079632679 0" xyz="0.104016 0.003308 -0.000027"/>
          <geometry>
            <cylinder length="0.219204" radius="0.065187"/>
          </geometry>
        </collision>
    </link>

    <joint name="pitch" type="revolute">
        <parent link="forearm"/>
        <child link="wrist_link"/>
        <origin rpy="-1.57079632679 -1.57079632679 0" xyz="0 0 0.31595760629823427"/>
        <axis xyz="0 0 1"/>
        <limit effort="200" lower="-1.57079637" upper="1.57079637" velocity=".26"/>
    </joint>







    <link name="end_effector">
        <inertial>
          <origin rpy="0 0 0" xyz="0.024426 -0.000000 -0.000014"/>
          <mass value="3.46114581082"/>
          <inertia ixx="0.00774521740658" ixy="0.0" ixz="0.0" iyy="0.00536142648454" iyz="0.0" izz="0.0055705568526"/>
        </inertial>

        <visual>
            <origin xyz="0 0 0" rpy="0 0 0"/>
            <geometry>
                <mesh filename="package://rexrov_dual_oberon_description/meshes/BaseGripper.stl"/>
            </geometry>
        </visual>

        <collision>
          <origin rpy="0 0 0" xyz="0.024426 -0.000000 -0.000014"/>
          <geometry>
            <box size="0.074326 0.117427 0.114298"/>
          </geometry>
        </collision>
    </link>

    <joint name="wrist" type="revolute">
        <parent link="wrist_link"/>
        <child link="end_effector"/>
        <origin rpy="3.1415 0 0" xyz="0.19304 0 0"/>
        <axis xyz="1 0 0"/>
        <limit effort="30" lower="-6.28318530718" upper="6.28318530718" velocity="0.15"/>
    </joint>

    <link name="finger_left">
        <inertial>
          <origin rpy="0 0 0" xyz="0.025268 -0.001931 -0.000079"/>
          <mass value="0.879770511849"/>
          <inertia ixx="0.000378330605849" ixy="0.0" ixz="0.0" iyy="0.000886148330217" iyz="0.0" izz="0.00091923080428"/>
        </inertial>

        <visual>
            <origin xyz="0 0 0" rpy="0 0 0"/>
            <geometry>
                <mesh filename="package://rexrov_dual_oberon_description/meshes/Finger.stl"/>
            </geometry>
        </visual>

        <collision>
            <origin xyz="0 0 0" rpy="0 0 0"/>
            <geometry>
                <mesh filename="package://rexrov_dual_oberon_description/meshes/Finger.stl"/>
            </geometry>
        </collision>
    </link>

    <joint name="finger_left_joint" type="revolute">
        <parent link="end_effector"/>
        <child link="finger_left"/>
        <origin xyz="0.0444267 0.0391376 0" rpy="0 0 0"/>
        <axis xyz="0 0 1"/>
        <limit effort="30" lower="0" upper="1.04709283144" velocity="0.15"/>
    </joint>

    <link name="finger_tip_left">
        <inertial>
          <origin rpy="0 0 0" xyz="0.027744 0.017278 0.0"/>
          <mass value="1.12550524054"/>
          <inertia ixx="0.000611047001819" ixy="0.0" ixz="0.0" iyy="0.00134903081039" iyz="0.0" izz="0.00121555609857"/>
        </inertial>

        <visual>
            <origin xyz="0 0 0" rpy="0 0 0"/>
            <geometry>
                <mesh filename="package://rexrov_dual_oberon_description/meshes/FingerTip.stl"/>
            </geometry>
        </visual>

        <collision>
            <origin xyz="0 0 0" rpy="0 0 0"/>
            <geometry>
                <mesh filename="package://rexrov_dual_oberon_description/meshes/FingerTip.stl"/>
            </geometry>
        </collision>
    </link>

    <joint name="finger_tip_left_joint" type="revolute">
        <parent link="finger_left"/>
        <child link="finger_tip_left"/>
        <origin rpy="3.14159265359 0 0" xyz="0.06431 0 0"/>
        <axis xyz="0 0 1"/>
        <limit effort="0" lower="-3.1415" upper="3.1415" velocity="0"/>
    </joint>

    <link name="finger_right">
        <inertial>
          <origin rpy="0 0 0" xyz="0.025268 -0.001931 -0.000079"/>
          <mass value="0.879770511849"/>
          <inertia ixx="0.000378330605849" ixy="0.0" ixz="0.0" iyy="0.000886148330217" iyz="0.0" izz="0.00091923080428"/>
        </inertial>

        <visual>
            <origin rpy="3.14159265359 0 0" xyz="0 0 0"/>
            <geometry>
                <mesh filename="package://rexrov_dual_oberon_description/meshes/Finger.stl"/>
            </geometry>
        </visual>

        <collision>
            <origin rpy="3.14159265359 0 0" xyz="0 0 0"/>
            <geometry>
                <mesh filename="package://rexrov_dual_oberon_description/meshes/Finger.stl"/>
            </geometry>
        </collision>
    </link>

    <joint name="finger_right_joint" type="revolute">
        <parent link="end_effector"/>
        <child link="finger_right"/>
        <origin rpy="3.14159265359 3.14159265359 3.14159265359" xyz="0.0444267 -0.0391376 0"/>
        <axis xyz="0 0 -1"/>
        <limit effort="30" lower="0" upper="1.04709283144" velocity="0.15"/>
    </joint>

    <link name="finger_tip_right">
        <inertial>
          <origin rpy="0 0 0" xyz="0.027744 0.017278 0.0"/>
          <mass value="1.12550524054"/>
          <inertia ixx="0.000611047001819" ixy="0.0" ixz="0.0" iyy="0.00134903081039" iyz="0.0" izz="0.00121555609857"/>
        </inertial>

        <visual>
            <origin xyz="0 0 0" rpy="0 0 0"/>
            <geometry>
                <mesh filename="package://rexrov_dual_oberon_description/meshes/FingerTip.stl"/>
            </geometry>
        </visual>

        <collision>
            <origin xyz="0 0 0" rpy="0 0 0"/>
            <geometry>
                <mesh filename="package://rexrov_dual_oberon_description/meshes/FingerTip.stl"/>
            </geometry>
        </collision>
    </link>

    <joint name="finger_tip_right_joint" type="revolute">
        <parent link="finger_right"/>
        <child link="finger_tip_right"/>
        <origin xyz="0.06431 0 0" rpy="0 0 0"/>
        <axis xyz="0 0 1"/>
        <limit effort="0" lower="-3.1415" upper="3.1415" velocity="0"/>
    </joint>    
</robot>