<?xml version="1.0" ?>
<sdf version="1.5">
  <model name="four_bar_sdf">
    <pose>0 0 0.04  0 0 0</pose>
    <self_collide>true</self_collide>
    <link name="linkROV">
      <pose>-0.2286 0 0 0 0 0</pose>
<!--       <inertial>
        <mass>0.048</mass>
        <inertia>
          <ixx>3.2000000000000003e-06</ixx>
          <iyy>0.00016160000000000002</iyy>
          <izz>0.00016160000000000002</izz>
          <ixy>0.0</ixy>
          <ixz>0.0</ixz>
          <iyz>0.0</iyz>
        </inertia>
      </inertial> -->
<!--       <inertial>
        <mass>76.8629</mass>
        <inertia>
          <ixx>1.7458</ixx>
          <iyy>2.3527</iyy>
          <izz>2.0709</izz>
          <ixy>0.0</ixy>
          <ixz>0.0</ixz>
          <iyz>0.0</iyz>
        </inertia>
      </inertial> -->
      <inertial>
        <mass>1.0</mass>
        <inertia>
          <ixx>0.0227</ixx>
          <iyy>0.0306</iyy>
          <izz>0.0269</izz>
          <ixy>0.0</ixy>
          <ixz>0.0</ixz>
          <iyz>0.0</iyz>
        </inertia>
      </inertial>
      <collision name="linkROV_collision">
        <geometry>
          <box>
            <size>0.4572 0.33805 0.39785</size>
          </box>
        </geometry>
      </collision>
      <visual name="linkROV_visual">
        <geometry>
          <box>
            <size>0.4572 0.33805 0.39785</size>
          </box>
        </geometry>
        <material>
          <color rgba="0.3 0.3 0.3 1.0"/>
        </material>
      </visual>
    </link>
    <link name="link1L">
      <pose>0.0575 0.1 -0.1 0.7854 0 0 </pose>
<!--       <inertial>
        <mass>0.07200000000000001</mass>
        <inertia>
          <ixx>0.0005424000000000002</ixx>
          <iyy>4.800000000000001e-06</iyy>
          <izz>0.0005424000000000002</izz>
          <ixy>0.0</ixy>
          <ixz>0.0</ixz>
          <iyz>0.0</iyz>
        </inertia>
      </inertial> -->
      <inertial>
        <mass>0.575</mass>
        <inertia>
          <ixx>3.8333e-05</ixx>
          <iyy>6.5286e-04</iyy>
          <izz>6.5286e-04</izz>
          <ixy>0.0</ixy>
          <ixz>0.0</ixz>
          <iyz>0.0</iyz>
        </inertia>
      </inertial>
      <collision name="link1L_collision">
        <geometry>
          <box>
            <size>0.115 0.02 0.02</size>
          </box>
        </geometry>
      </collision>
      <visual name="link1L_visual">
        <geometry>
          <box>
            <size>0.115 0.02 0.02</size>
          </box>
        </geometry>
        <material>
          <color rgba="0.3 0.3 0.3 1.0"/>
        </material>
      </visual>
    </link>
    <link name="link2L">
      <pose>0.15 0.14287 -0.057134 0.46365 -0.65906 0.88608 </pose>
      <inertial>
        <mass>0.700</mass>
        <inertia>
          <ixx>4.6667e-05</ixx>
          <iyy>1.1667e-03</iyy>
          <izz>1.1667e-03</izz>
          <ixy>0.0</ixy>
          <ixz>0.0</ixz>
          <iyz>0.0</iyz>
        </inertia>
      </inertial>
      <!-- <inertial>
        <mass>0.07200000000000001</mass>
        <inertia>
          <ixx>0.0005424000000000002</ixx>
          <iyy>4.800000000000001e-06</iyy>
          <izz>0.0005424000000000002</izz>
          <ixy>0.0</ixy>
          <ixz>0.0</ixz>
          <iyz>0.0</iyz>
        </inertia>
      </inertial> -->
      <collision name="link2L_collision">
        <geometry>
          <box>
            <size>0.140 0.02 0.02</size>
          </box>
        </geometry>
      </collision>
      <visual name="link2L_visual">
        <geometry>
          <box>
            <size>0.140 0.02 0.02</size>
          </box>
        </geometry>
        <material>
          <color rgba="0.3 0.3 0.3 1.0"/>
        </material>
      </visual>
    </link>
    <link name="link3L">
      <pose>0.2425 0.18573 -0.014268 0.7854 0 5.5511e-17 </pose>
      <inertial>
        <mass>0.575</mass>
        <inertia>
          <ixx>3.8333e-05</ixx>
          <iyy>6.5286e-04</iyy>
          <izz>6.5286e-04</izz>
          <ixy>0.0</ixy>
          <ixz>0.0</ixz>
          <iyz>0.0</iyz>
        </inertia>
      </inertial>
      <!-- <inertial>
        <mass>0.07200000000000001</mass>
        <inertia>
          <ixx>0.0005424000000000002</ixx>
          <iyy>4.800000000000001e-06</iyy>
          <izz>0.0005424000000000002</izz>
          <ixy>0.0</ixy>
          <ixz>0.0</ixz>
          <iyz>0.0</iyz>
        </inertia>
      </inertial> -->
      <collision name="link3L_collision">
        <geometry>
          <box>
            <size>0.115 0.02 0.02</size>
          </box>
        </geometry>
      </collision>
      <visual name="link3L_visual">
        <geometry>
          <box>
            <size>0.115 0.02 0.02</size>
          </box>
        </geometry>
        <material>
          <color rgba="0.3 0.3 0.3 1.0"/>
        </material>
      </visual>
    </link>
    <link name="link4L">
      <pose>0.35 0.18573 -0.014268 0 0 5.5511e-17 </pose>
      <inertial>
        <mass>0.500</mass>
        <inertia>
          <ixx>3.3333e-05</ixx>
          <iyy>4.3333e-04</iyy>
          <izz>4.3333e-04</izz>
          <ixy>0.0</ixy>
          <ixz>0.0</ixz>
          <iyz>0.0</iyz>
        </inertia>
      </inertial>
      <!-- <inertial>
        <mass>0.07200000000000001</mass>
        <inertia>
          <ixx>0.0005424000000000002</ixx>
          <iyy>4.800000000000001e-06</iyy>
          <izz>0.0005424000000000002</izz>
          <ixy>0.0</ixy>
          <ixz>0.0</ixz>
          <iyz>0.0</iyz>
        </inertia>
      </inertial> -->
      <collision name="link4L_collision">
        <geometry>
          <box>
            <size>0.100 0.02 0.02</size>
          </box>
        </geometry>
      </collision>
      <visual name="link4L_visual">
        <geometry>
          <box>
            <size>0.100 0.02 0.02</size>
          </box>
        </geometry>
        <material>
          <color rgba="0.3 0.3 0.3 1.0"/>
        </material>
      </visual>
    </link>
    <link name="link5L">
      <pose>0.4575 0.18573 -0.014268 0 0 5.5511e-17 </pose>
      <inertial>
        <mass>0.575</mass>
        <inertia>
          <ixx>3.8333e-05</ixx>
          <iyy>6.5286e-04</iyy>
          <izz>6.5286e-04</izz>
          <ixy>0.0</ixy>
          <ixz>0.0</ixz>
          <iyz>0.0</iyz>
        </inertia>
      </inertial>
      <!-- <inertial>
        <mass>0.07200000000000001</mass>
        <inertia>
          <ixx>0.0005424000000000002</ixx>
          <iyy>4.800000000000001e-06</iyy>
          <izz>0.0005424000000000002</izz>
          <ixy>0.0</ixy>
          <ixz>0.0</ixz>
          <iyz>0.0</iyz>
        </inertia>
      </inertial> -->
      <collision name="link5L_collision">
        <geometry>
          <box>
            <size>0.115 0.02 0.02</size>
          </box>
        </geometry>
      </collision>
      <visual name="link5L_visual">
        <geometry>
          <box>
            <size>0.115 0.02 0.02</size>
          </box>
        </geometry>
        <material>
          <color rgba="0.3 0.3 0.3 1.0"/>
        </material>
      </visual>
    </link>
    <link name="link6L">
      <pose>0.575 0.18573 -0.014268 0 0 5.5511e-17 </pose>
      <inertial>
        <mass>0.600</mass>
        <inertia>
          <ixx>4.0000e-05</ixx>
          <iyy>7.4000e-04</iyy>
          <izz>7.4000e-04</izz>
          <ixy>0.0</ixy>
          <ixz>0.0</ixz>
          <iyz>0.0</iyz>
        </inertia>
      </inertial>
      <!-- <inertial>
        <mass>0.07200000000000001</mass>
        <inertia>
          <ixx>0.0005424000000000002</ixx>
          <iyy>4.800000000000001e-06</iyy>
          <izz>0.0005424000000000002</izz>
          <ixy>0.0</ixy>
          <ixz>0.0</ixz>
          <iyz>0.0</iyz>
        </inertia>
      </inertial> -->
      <collision name="link6L_collision">
        <geometry>
          <box>
            <size>0.120 0.02 0.02</size>
          </box>
        </geometry>
      </collision>
      <visual name="link6L_visual">
        <geometry>
          <box>
            <size>0.120 0.02 0.02</size>
          </box>
        </geometry>
        <material>
          <color rgba="0.3 0.3 0.3 1.0"/>
        </material>
      </visual>
    </link>






    <link name="link1R">
      <pose>0.0575 -0.1 -0.1 -0.7854 0 0 </pose>
      <inertial>
        <mass>0.575</mass>
        <inertia>
          <ixx>3.8333e-05</ixx>
          <iyy>6.5286e-04</iyy>
          <izz>6.5286e-04</izz>
          <ixy>0.0</ixy>
          <ixz>0.0</ixz>
          <iyz>0.0</iyz>
        </inertia>
      </inertial>
      <!-- <inertial>
        <mass>0.07200000000000001</mass>
        <inertia>
          <ixx>0.0005424000000000002</ixx>
          <iyy>4.800000000000001e-06</iyy>
          <izz>0.0005424000000000002</izz>
          <ixy>0.0</ixy>
          <ixz>0.0</ixz>
          <iyz>0.0</iyz>
        </inertia>
      </inertial> -->
      <collision name="link1R_collision">
        <geometry>
          <box>
            <size>0.115 0.02 0.02</size>
          </box>
        </geometry>
      </collision>
      <visual name="link1R_visual">
        <geometry>
          <box>
            <size>0.115 0.02 0.02</size>
          </box>
        </geometry>
        <material>
          <color rgba="0.3 0.3 0.3 1.0"/>
        </material>
      </visual>
    </link>
    <link name="link2R">
      <pose>0.15 -0.14287 -0.057134 -0.46365 -0.65906 -0.88608 </pose>
      <inertial>
        <mass>0.700</mass>
        <inertia>
          <ixx>4.6667e-05</ixx>
          <iyy>1.1667e-03</iyy>
          <izz>1.1667e-03</izz>
          <ixy>0.0</ixy>
          <ixz>0.0</ixz>
          <iyz>0.0</iyz>
        </inertia>
      </inertial>
      <!-- <inertial>
        <mass>0.07200000000000001</mass>
        <inertia>
          <ixx>0.0005424000000000002</ixx>
          <iyy>4.800000000000001e-06</iyy>
          <izz>0.0005424000000000002</izz>
          <ixy>0.0</ixy>
          <ixz>0.0</ixz>
          <iyz>0.0</iyz>
        </inertia>
      </inertial> -->
      <collision name="link2R_collision">
        <geometry>
          <box>
            <size>0.140 0.02 0.02</size>
          </box>
        </geometry>
      </collision>
      <visual name="link2R_visual">
        <geometry>
          <box>
            <size>0.140 0.02 0.02</size>
          </box>
        </geometry>
        <material>
          <color rgba="0.3 0.3 0.3 1.0"/>
        </material>
      </visual>
    </link>
    <link name="link3R">
      <pose>0.2425 -0.18573 -0.014268 -0.7854 0 -5.5511e-17 </pose>
      <inertial>
        <mass>0.575</mass>
        <inertia>
          <ixx>3.8333e-05</ixx>
          <iyy>6.5286e-04</iyy>
          <izz>6.5286e-04</izz>
          <ixy>0.0</ixy>
          <ixz>0.0</ixz>
          <iyz>0.0</iyz>
        </inertia>
      </inertial>
      <!-- <inertial>
        <mass>0.07200000000000001</mass>
        <inertia>
          <ixx>0.0005424000000000002</ixx>
          <iyy>4.800000000000001e-06</iyy>
          <izz>0.0005424000000000002</izz>
          <ixy>0.0</ixy>
          <ixz>0.0</ixz>
          <iyz>0.0</iyz>
        </inertia>
      </inertial> -->
      <collision name="link3R_collision">
        <geometry>
          <box>
            <size>0.115 0.02 0.02</size>
          </box>
        </geometry>
      </collision>
      <visual name="link3R_visual">
        <geometry>
          <box>
            <size>0.115 0.02 0.02</size>
          </box>
        </geometry>
        <material>
          <color rgba="0.3 0.3 0.3 1.0"/>
        </material>
      </visual>
    </link>
    <link name="link4R">
      <pose>0.35 -0.18573 -0.014268 0 0 -5.5511e-17 </pose>
      <inertial>
        <mass>0.500</mass>
        <inertia>
          <ixx>3.3333e-05</ixx>
          <iyy>4.3333e-04</iyy>
          <izz>4.3333e-04</izz>
          <ixy>0.0</ixy>
          <ixz>0.0</ixz>
          <iyz>0.0</iyz>
        </inertia>
      </inertial>
      <!-- <inertial>
        <mass>0.07200000000000001</mass>
        <inertia>
          <ixx>0.0005424000000000002</ixx>
          <iyy>4.800000000000001e-06</iyy>
          <izz>0.0005424000000000002</izz>
          <ixy>0.0</ixy>
          <ixz>0.0</ixz>
          <iyz>0.0</iyz>
        </inertia>
      </inertial> -->
      <collision name="link4R_collision">
        <geometry>
          <box>
            <size>0.100 0.02 0.02</size>
          </box>
        </geometry>
      </collision>
      <visual name="link4R_visual">
        <geometry>
          <box>
            <size>0.100 0.02 0.02</size>
          </box>
        </geometry>
        <material>
          <color rgba="0.3 0.3 0.3 1.0"/>
        </material>
      </visual>
    </link>
    <link name="link5R">
      <pose>0.4575 -0.18573 -0.014268 0 0 -5.5511e-17 </pose>
      <inertial>
        <mass>0.575</mass>
        <inertia>
          <ixx>3.8333e-05</ixx>
          <iyy>6.5286e-04</iyy>
          <izz>6.5286e-04</izz>
          <ixy>0.0</ixy>
          <ixz>0.0</ixz>
          <iyz>0.0</iyz>
        </inertia>
      </inertial>
      <!-- <inertial>
        <mass>0.07200000000000001</mass>
        <inertia>
          <ixx>0.0005424000000000002</ixx>
          <iyy>4.800000000000001e-06</iyy>
          <izz>0.0005424000000000002</izz>
          <ixy>0.0</ixy>
          <ixz>0.0</ixz>
          <iyz>0.0</iyz>
        </inertia>
      </inertial> -->
      <collision name="link5R_collision">
        <geometry>
          <box>
            <size>0.115 0.02 0.02</size>
          </box>
        </geometry>
      </collision>
      <visual name="link5R_visual">
        <geometry>
          <box>
            <size>0.115 0.02 0.02</size>
          </box>
        </geometry>
        <material>
          <color rgba="0.3 0.3 0.3 1.0"/>
        </material>
      </visual>
    </link>
    <link name="link6R">
      <pose>0.575 -0.18573 -0.014268 0 0 -5.5511e-17 </pose>
      <inertial>
        <mass>0.600</mass>
        <inertia>
          <ixx>4.0000e-05</ixx>
          <iyy>7.4000e-04</iyy>
          <izz>7.4000e-04</izz>
          <ixy>0.0</ixy>
          <ixz>0.0</ixz>
          <iyz>0.0</iyz>
        </inertia>
      </inertial>
      <!-- <inertial>
        <mass>0.07200000000000001</mass>
        <inertia>
          <ixx>0.0005424000000000002</ixx>
          <iyy>4.800000000000001e-06</iyy>
          <izz>0.0005424000000000002</izz>
          <ixy>0.0</ixy>
          <ixz>0.0</ixz>
          <iyz>0.0</iyz>
        </inertia>
      </inertial> -->
      <collision name="link6R_collision">
        <geometry>
          <box>
            <size>0.120 0.02 0.02</size>
          </box>
        </geometry>
      </collision>
      <visual name="link6R_visual">
        <geometry>
          <box>
            <size>0.120 0.02 0.02</size>
          </box>
        </geometry>
        <material>
          <color rgba="0.3 0.3 0.3 1.0"/>
        </material>
      </visual>
    </link>






<!--     <joint name="joint_base" type="fixed">
      <pose>-0.0575 0 0 0 0 0</pose>
      <parent>world</parent>
      <child>linkROV</child>
    </joint> -->
    <joint name="joint_gripL" type="fixed">
      <pose>0 0 0 0 0 0</pose>
      <parent>world</parent>
      <child>link6L</child>
    </joint>
    <joint name="joint_1L" type="revolute">
      <pose>0 0 0 0 0 0</pose>
      <parent>linkROV</parent>
      <child>link1L</child>
      <axis>
        <xyz>1 0 0</xyz>
        <dynamics>
          <damping>0.05</damping>
          <friction>0</friction>
          <spring_reference>0</spring_reference>
          <spring_stiffness>10.0</spring_stiffness>
        </dynamics>
      </axis>
    </joint>
    <joint name="joint_2L" type="revolute">
      <pose>-0.07 0 0 0 0 0</pose>
      <parent>link1L</parent>
      <child>link2L</child>
      <axis>
        <xyz>0 0 1</xyz>
        <dynamics>
          <damping>0.05</damping>
          <friction>0</friction>
          <spring_reference>0</spring_reference>
          <spring_stiffness>10.0</spring_stiffness>
        </dynamics>
      </axis>
    </joint>
    <joint name="joint_3L" type="revolute">
      <pose>-0.0575 0 0 0 0 0</pose>
      <parent>link2L</parent>
      <child>link3L</child>
      <axis>
        <xyz>0 0 1</xyz>
        <dynamics>
          <damping>0.05</damping>
          <friction>0</friction>
          <spring_reference>0</spring_reference>
          <spring_stiffness>10.0</spring_stiffness>
        </dynamics>
      </axis>
    </joint>
    <joint name="joint_4L" type="revolute">
      <pose>-0.05 0 0 0 0 0</pose>
      <parent>link3L</parent>
      <child>link4L</child>
      <axis>
        <xyz>1 0 0</xyz>
        <dynamics>
          <damping>0.05</damping>
          <friction>0</friction>
          <spring_reference>0</spring_reference>
          <spring_stiffness>10.0</spring_stiffness>
        </dynamics>
      </axis>
    </joint>
    <joint name="joint_5L" type="revolute">
      <pose>-0.0575 0 0 0 0 0</pose>
      <parent>link4L</parent>
      <child>link5L</child>
      <axis>
        <xyz>0 0 1</xyz>
        <dynamics>
          <damping>0.05</damping>
          <friction>0</friction>
          <spring_reference>0</spring_reference>
          <spring_stiffness>10.0</spring_stiffness>
        </dynamics>
      </axis>
    </joint>
    <joint name="joint_6L" type="revolute">
      <pose>-0.06 0 0 0 0 0</pose>
      <parent>link5L</parent>
      <child>link6L</child>
      <axis>
        <xyz>1 0 0</xyz>
        <dynamics>
          <damping>0.05</damping>
          <friction>0</friction>
          <spring_reference>0</spring_reference>
          <spring_stiffness>10.0</spring_stiffness>
        </dynamics>
      </axis>
    </joint>







    <joint name="joint_gripR" type="fixed">
      <pose>0 0 0 0 0 0</pose>
      <parent>world</parent>
      <child>link6R</child>
    </joint>
    <joint name="joint_1R" type="revolute">
      <pose>0 0 0 0 0 0</pose>
      <parent>linkROV</parent>
      <child>link1R</child>
      <axis>
        <xyz>1 0 0</xyz>
        <dynamics>
          <damping>0.05</damping>
          <friction>0</friction>
          <spring_reference>0</spring_reference>
          <spring_stiffness>10.0</spring_stiffness>
        </dynamics>
      </axis>
    </joint>
    <joint name="joint_2R" type="revolute">
      <pose>-0.07 0 0 0 0 0</pose>
      <parent>link1R</parent>
      <child>link2R</child>
      <axis>
        <xyz>0 0 1</xyz>
        <dynamics>
          <damping>0.05</damping>
          <friction>0</friction>
          <spring_reference>0</spring_reference>
          <spring_stiffness>10.0</spring_stiffness>
        </dynamics>
      </axis>
    </joint>
    <joint name="joint_3R" type="revolute">
      <pose>-0.0575 0 0 0 0 0</pose>
      <parent>link2R</parent>
      <child>link3R</child>
      <axis>
        <xyz>0 0 1</xyz>
        <dynamics>
          <damping>0.05</damping>
          <friction>0</friction>
          <spring_reference>0</spring_reference>
          <spring_stiffness>10.0</spring_stiffness>
        </dynamics>
      </axis>
    </joint>
    <joint name="joint_4R" type="revolute">
      <pose>-0.05 0 0 0 0 0</pose>
      <parent>link3R</parent>
      <child>link4R</child>
      <axis>
        <xyz>1 0 0</xyz>
        <dynamics>
          <damping>0.05</damping>
          <friction>0</friction>
          <spring_reference>0</spring_reference>
          <spring_stiffness>10.0</spring_stiffness>
        </dynamics>
      </axis>
    </joint>
    <joint name="joint_5R" type="revolute">
      <pose>-0.0575 0 0 0 0 0</pose>
      <parent>link4R</parent>
      <child>link5R</child>
      <axis>
        <xyz>0 0 1</xyz>
        <dynamics>
          <damping>0.05</damping>
          <friction>0</friction>
          <spring_reference>0</spring_reference>
          <spring_stiffness>10.0</spring_stiffness>
        </dynamics>
      </axis>
    </joint>
    <joint name="joint_6R" type="revolute">
      <pose>-0.06 0 0 0 0 0</pose>
      <parent>link5R</parent>
      <child>link6R</child>
      <axis>
        <xyz>1 0 0</xyz>
        <dynamics>
          <damping>0.05</damping>
          <friction>0</friction>
          <spring_reference>0</spring_reference>
          <spring_stiffness>10.0</spring_stiffness>
        </dynamics>
      </axis>
    </joint>
  </model>
</sdf>