<?xml version="1.0"?>

<robot xmlns:xacro="http://www.ros.org/wiki/xacro">

    <link name="${namespace}/end_effector">
        <xacro:link_box_inertial mass="${total_mass * gripper_base_volume / total_volume}"
                    width="${gripper_base_width}"
                    length="${gripper_base_length}"
                    height="${gripper_base_height}">
        <origin xyz="${gripper_base_com}" rpy="0 0 0"/>
        </xacro:link_box_inertial>

        <visual>
            <origin xyz="0 0 0" rpy="0 0 0"/>
            <geometry>
                <mesh filename="file://$(find oberon7_lite)/meshes/parallel_gripper/visual/BaseGripper.dae"/>
            </geometry>
        </visual>

        <collision>
            <origin xyz="${gripper_base_com}" rpy="0 0 0"/>
            <geometry>
                <box size="1e-9 1e-9 1e-9"/>
            </geometry>
        </collision>
    </link>

    <joint name="${namespace}/wrist" type="revolute">
      <parent link="${namespace}/wrist_link"/>
      <child link="${namespace}/end_effector"/>
       <origin xyz="0.19304 0 0" rpy="${-PI*0.5} 0 0"/>
      <axis xyz="1 0 0"/>
      <dynamics damping="0.10" friction="0.05"/>
      <!-- <dynamics damping="10" friction="0"/> -->
      <limit effort="10" lower="${-2*PI}" upper="${2*PI}" velocity="${gripper_velocity}"/>
    </joint>

    <xacro:simple_transmission joint="${namespace}/wrist" />

    <link name="${namespace}/finger_left">
        <xacro:link_box_inertial mass="${total_mass * finger_volume / total_volume}"
                    width="${finger_width}"
                    length="${finger_length}"
                    height="${finger_height}">
        <origin xyz="${finger_com}" rpy="0 0 0"/>
        </xacro:link_box_inertial>

        <visual>
            <origin xyz="0 0 0" rpy="0 0 0"/>
            <geometry>
                <mesh filename="file://$(find oberon7_lite)/meshes/parallel_gripper/visual/Finger.dae"/>
            </geometry>
        </visual>

        <collision>
            <origin xyz="0 0 0" rpy="0 0 0"/>
            <geometry>
                <box size="1e-9 1e-9 1e-9"/>
            </geometry>
        </collision>
    </link>

    <joint name="${namespace}/finger_left_joint" type="revolute">
        <parent link="${namespace}/end_effector"/>
        <child link="${namespace}/finger_left"/>
        <origin xyz="0.0444267 0.0391376 0" rpy="0 0 0"/>
        <axis xyz="0 0 1"/>
        <dynamics damping="0.05" friction="0.01"/>
        <!-- <dynamics damping="5" friction="0"/> -->
        <limit effort="${gripper_effort}" lower="0" upper="${PI*0.3333}" velocity="${gripper_velocity}"/>
    </joint>

    <xacro:simple_transmission joint="${namespace}/finger_left_joint" />

    <link name="${namespace}/finger_tip_left">
        <xacro:link_box_inertial mass="${total_mass * finger_tip_volume / total_volume}"
                    width="${finger_tip_width}"
                    length="${finger_tip_length}"
                    height="${finger_tip_height}">
        <origin xyz="${finger_tip_com}" rpy="0 0 0"/>
        </xacro:link_box_inertial>

        <visual>
            <origin xyz="0 0 0" rpy="0 0 0"/>
            <geometry>
                <mesh filename="file://$(find oberon7_lite)/meshes/parallel_gripper/visual/FingerTip.dae"/>
            </geometry>
        </visual>

        <collision>
            <origin xyz="0 0 0" rpy="0 0 0"/>
            <geometry>
                <box size="1e-9 1e-9 1e-9"/>
            </geometry>
        </collision>
    </link>

    <joint name="${namespace}/finger_tip_left_joint" type="revolute">
        <parent link="${namespace}/finger_left"/>
        <child link="${namespace}/finger_tip_left"/>
        <origin xyz="0.06431 0 0" rpy="${PI} 0 0"/>
        <axis xyz="0 0 1"/>
        <dynamics damping="0.05" friction="0.01"/>
        <!-- <dynamics damping="5" friction="0"/> -->
        <limit effort="0" lower="0" upper="0" velocity="0"/>
    </joint>

    <link name="${namespace}/finger_right">
        <xacro:link_box_inertial mass="${total_mass * finger_volume / total_volume}"
                    width="${finger_width}"
                    length="${finger_length}"
                    height="${finger_height}">
        <origin xyz="${finger_com}" rpy="0 0 0"/>
        </xacro:link_box_inertial>

        <visual>
            <origin xyz="0 0 0" rpy="${PI} 0 0"/>
            <geometry>
                <mesh filename="file://$(find oberon7_lite)/meshes/parallel_gripper/visual/Finger.dae"/>
            </geometry>
        </visual>

        <collision>
            <origin xyz="0 0 0" rpy="${PI} 0 0"/>
            <geometry>
                <box size="1e-9 1e-9 1e-9"/>
            </geometry>
        </collision>
    </link>

    <joint name="${namespace}/finger_right_joint" type="revolute">
        <parent link="${namespace}/end_effector"/>
        <child link="${namespace}/finger_right"/>
        <origin xyz="0.0444267 -0.0391376 0" rpy="${PI} ${PI} ${PI}"/>
        <axis xyz="0 0 -1"/>
        <dynamics damping="0.05" friction="0.01"/>
        <!-- <dynamics damping="10" friction="0"/> -->
        <limit effort="${gripper_effort}" lower="0" upper="${PI*0.3333}" velocity="${gripper_velocity}"/>
    </joint>

    <xacro:simple_transmission joint="${namespace}/finger_right_joint" />

    <link name="${namespace}/finger_tip_right">
        <xacro:link_box_inertial mass="${total_mass * finger_tip_volume / total_volume}"
                    width="${finger_tip_width}"
                    length="${finger_tip_length}"
                    height="${finger_tip_height}">
        <origin xyz="${finger_tip_com}" rpy="0 0 0"/>
        </xacro:link_box_inertial>

        <visual>
            <origin xyz="0 0 0" rpy="0 0 0"/>
            <geometry>
                <mesh filename="file://$(find oberon7_lite)/meshes/parallel_gripper/visual/FingerTip.dae"/>
            </geometry>
        </visual>

        <collision>
            <origin xyz="0 0 0" rpy="0 0 0"/>
            <geometry>
                <box size="1e-9 1e-9 1e-9"/>
            </geometry>
        </collision>
    </link>

    <joint name="${namespace}/finger_tip_right_joint" type="revolute">
        <parent link="${namespace}/finger_right"/>
        <child link="${namespace}/finger_tip_right"/>
        <origin xyz="0.06431 0 0" rpy="0 0 0"/>
        <axis xyz="0 0 1"/>
        <dynamics damping="0.05" friction="0.01"/>
        <!-- <dynamics damping="5" friction="0"/> -->
        <limit effort="0" lower="0" upper="0" velocity="0"/>
    </joint>

</robot>
